[2024-08-23 10:38:24,940] {taskinstance.py:1159} INFO - Dependencies all met for <TaskInstance: climate_data.extract_data scheduled__2024-08-05T00:00:00+00:00 [queued]>
[2024-08-23 10:38:24,944] {taskinstance.py:1159} INFO - Dependencies all met for <TaskInstance: climate_data.extract_data scheduled__2024-08-05T00:00:00+00:00 [queued]>
[2024-08-23 10:38:24,944] {taskinstance.py:1356} INFO - 
--------------------------------------------------------------------------------
[2024-08-23 10:38:24,944] {taskinstance.py:1357} INFO - Starting attempt 1 of 1
[2024-08-23 10:38:24,944] {taskinstance.py:1358} INFO - 
--------------------------------------------------------------------------------
[2024-08-23 10:38:24,952] {taskinstance.py:1377} INFO - Executing <Task(PythonOperator): extract_data> on 2024-08-05 00:00:00+00:00
[2024-08-23 10:38:24,955] {standard_task_runner.py:52} INFO - Started process 37420 to run task
[2024-08-23 10:38:24,956] {standard_task_runner.py:79} INFO - Running: ['airflow', 'tasks', 'run', 'climate_data', 'extract_data', 'scheduled__2024-08-05T00:00:00+00:00', '--job-id', '10', '--raw', '--subdir', 'DAGS_FOLDER/climate_data.py', '--cfg-path', '/tmp/tmp08vmw7qf', '--error-file', '/tmp/tmpaavbs1bs']
[2024-08-23 10:38:24,956] {standard_task_runner.py:80} INFO - Job 10: Subtask extract_data
[2024-08-23 10:38:24,978] {task_command.py:370} INFO - Running <TaskInstance: climate_data.extract_data scheduled__2024-08-05T00:00:00+00:00 [running]> on host DESKTOP-TAQHM1V.
[2024-08-23 10:38:24,993] {taskinstance.py:1889} ERROR - Task failed with exception
Traceback (most recent call last):
  File "/root/Documentos/pipeline-airflow/venv/lib/python3.10/site-packages/airflow/models/taskinstance.py", line 1451, in _run_raw_task
    self._execute_task_with_callbacks(context, test_mode)
  File "/root/Documentos/pipeline-airflow/venv/lib/python3.10/site-packages/airflow/models/taskinstance.py", line 1555, in _execute_task_with_callbacks
    task_orig = self.render_templates(context=context)
  File "/root/Documentos/pipeline-airflow/venv/lib/python3.10/site-packages/airflow/models/taskinstance.py", line 2212, in render_templates
    rendered_task = self.task.render_template_fields(context)
  File "/root/Documentos/pipeline-airflow/venv/lib/python3.10/site-packages/airflow/models/baseoperator.py", line 1185, in render_template_fields
    self._do_render_template_fields(self, self.template_fields, context, jinja_env, set())
  File "/root/Documentos/pipeline-airflow/venv/lib/python3.10/site-packages/airflow/utils/session.py", line 71, in wrapper
    return func(*args, session=session, **kwargs)
  File "/root/Documentos/pipeline-airflow/venv/lib/python3.10/site-packages/airflow/models/abstractoperator.py", line 344, in _do_render_template_fields
    rendered_content = self.render_template(
  File "/root/Documentos/pipeline-airflow/venv/lib/python3.10/site-packages/airflow/models/abstractoperator.py", line 404, in render_template
    return {key: self.render_template(value, context, jinja_env) for key, value in value.items()}
  File "/root/Documentos/pipeline-airflow/venv/lib/python3.10/site-packages/airflow/models/abstractoperator.py", line 404, in <dictcomp>
    return {key: self.render_template(value, context, jinja_env) for key, value in value.items()}
  File "/root/Documentos/pipeline-airflow/venv/lib/python3.10/site-packages/airflow/models/abstractoperator.py", line 387, in render_template
    template = jinja_env.from_string(value)
  File "/root/Documentos/pipeline-airflow/venv/lib/python3.10/site-packages/jinja2/environment.py", line 1092, in from_string
    return cls.from_code(self, self.compile(source), gs, None)
  File "/root/Documentos/pipeline-airflow/venv/lib/python3.10/site-packages/jinja2/environment.py", line 757, in compile
    self.handle_exception(source=source_hint)
  File "/root/Documentos/pipeline-airflow/venv/lib/python3.10/site-packages/jinja2/environment.py", line 925, in handle_exception
    raise rewrite_traceback_stack(source=source)
  File "<unknown>", line 1, in template
jinja2.exceptions.TemplateSyntaxError: unexpected '%'
[2024-08-23 10:38:24,996] {taskinstance.py:1395} INFO - Marking task as FAILED. dag_id=climate_data, task_id=extract_data, execution_date=20240805T000000, start_date=20240823T133824, end_date=20240823T133824
[2024-08-23 10:38:25,002] {standard_task_runner.py:92} ERROR - Failed to execute job 10 for task extract_data (unexpected '%'; 37420)
[2024-08-23 10:38:25,008] {local_task_job.py:156} INFO - Task exited with return code 1
[2024-08-23 10:38:25,019] {local_task_job.py:273} INFO - 0 downstream tasks scheduled from follow-on schedule check
[2024-08-23 10:40:48,265] {taskinstance.py:1159} INFO - Dependencies all met for <TaskInstance: climate_data.extract_data scheduled__2024-08-05T00:00:00+00:00 [queued]>
[2024-08-23 10:40:48,270] {taskinstance.py:1159} INFO - Dependencies all met for <TaskInstance: climate_data.extract_data scheduled__2024-08-05T00:00:00+00:00 [queued]>
[2024-08-23 10:40:48,270] {taskinstance.py:1356} INFO - 
--------------------------------------------------------------------------------
[2024-08-23 10:40:48,270] {taskinstance.py:1357} INFO - Starting attempt 1 of 1
[2024-08-23 10:40:48,270] {taskinstance.py:1358} INFO - 
--------------------------------------------------------------------------------
[2024-08-23 10:40:48,279] {taskinstance.py:1377} INFO - Executing <Task(PythonOperator): extract_data> on 2024-08-05 00:00:00+00:00
[2024-08-23 10:40:48,281] {standard_task_runner.py:52} INFO - Started process 38438 to run task
[2024-08-23 10:40:48,283] {standard_task_runner.py:79} INFO - Running: ['airflow', 'tasks', 'run', 'climate_data', 'extract_data', 'scheduled__2024-08-05T00:00:00+00:00', '--job-id', '10', '--raw', '--subdir', 'DAGS_FOLDER/climate_data.py', '--cfg-path', '/tmp/tmp07p930pi', '--error-file', '/tmp/tmp2q4_r87e']
[2024-08-23 10:40:48,283] {standard_task_runner.py:80} INFO - Job 10: Subtask extract_data
[2024-08-23 10:40:48,309] {task_command.py:370} INFO - Running <TaskInstance: climate_data.extract_data scheduled__2024-08-05T00:00:00+00:00 [running]> on host DESKTOP-TAQHM1V.
[2024-08-23 10:40:48,332] {taskinstance.py:1889} ERROR - Task failed with exception
Traceback (most recent call last):
  File "/root/Documentos/pipeline-airflow/venv/lib/python3.10/site-packages/airflow/models/taskinstance.py", line 1451, in _run_raw_task
    self._execute_task_with_callbacks(context, test_mode)
  File "/root/Documentos/pipeline-airflow/venv/lib/python3.10/site-packages/airflow/models/taskinstance.py", line 1555, in _execute_task_with_callbacks
    task_orig = self.render_templates(context=context)
  File "/root/Documentos/pipeline-airflow/venv/lib/python3.10/site-packages/airflow/models/taskinstance.py", line 2212, in render_templates
    rendered_task = self.task.render_template_fields(context)
  File "/root/Documentos/pipeline-airflow/venv/lib/python3.10/site-packages/airflow/models/baseoperator.py", line 1185, in render_template_fields
    self._do_render_template_fields(self, self.template_fields, context, jinja_env, set())
  File "/root/Documentos/pipeline-airflow/venv/lib/python3.10/site-packages/airflow/utils/session.py", line 71, in wrapper
    return func(*args, session=session, **kwargs)
  File "/root/Documentos/pipeline-airflow/venv/lib/python3.10/site-packages/airflow/models/abstractoperator.py", line 344, in _do_render_template_fields
    rendered_content = self.render_template(
  File "/root/Documentos/pipeline-airflow/venv/lib/python3.10/site-packages/airflow/models/abstractoperator.py", line 404, in render_template
    return {key: self.render_template(value, context, jinja_env) for key, value in value.items()}
  File "/root/Documentos/pipeline-airflow/venv/lib/python3.10/site-packages/airflow/models/abstractoperator.py", line 404, in <dictcomp>
    return {key: self.render_template(value, context, jinja_env) for key, value in value.items()}
  File "/root/Documentos/pipeline-airflow/venv/lib/python3.10/site-packages/airflow/models/abstractoperator.py", line 387, in render_template
    template = jinja_env.from_string(value)
  File "/root/Documentos/pipeline-airflow/venv/lib/python3.10/site-packages/jinja2/environment.py", line 1092, in from_string
    return cls.from_code(self, self.compile(source), gs, None)
  File "/root/Documentos/pipeline-airflow/venv/lib/python3.10/site-packages/jinja2/environment.py", line 757, in compile
    self.handle_exception(source=source_hint)
  File "/root/Documentos/pipeline-airflow/venv/lib/python3.10/site-packages/jinja2/environment.py", line 925, in handle_exception
    raise rewrite_traceback_stack(source=source)
  File "<unknown>", line 1, in template
jinja2.exceptions.TemplateSyntaxError: unexpected '%'
[2024-08-23 10:40:48,335] {taskinstance.py:1395} INFO - Marking task as FAILED. dag_id=climate_data, task_id=extract_data, execution_date=20240805T000000, start_date=20240823T134048, end_date=20240823T134048
[2024-08-23 10:40:48,345] {standard_task_runner.py:92} ERROR - Failed to execute job 10 for task extract_data (unexpected '%'; 38438)
[2024-08-23 10:40:48,376] {local_task_job.py:156} INFO - Task exited with return code 1
[2024-08-23 10:40:48,385] {local_task_job.py:273} INFO - 0 downstream tasks scheduled from follow-on schedule check
[2024-08-23 10:44:35,071] {taskinstance.py:1159} INFO - Dependencies all met for <TaskInstance: climate_data.extract_data scheduled__2024-08-05T00:00:00+00:00 [queued]>
[2024-08-23 10:44:35,075] {taskinstance.py:1159} INFO - Dependencies all met for <TaskInstance: climate_data.extract_data scheduled__2024-08-05T00:00:00+00:00 [queued]>
[2024-08-23 10:44:35,075] {taskinstance.py:1356} INFO - 
--------------------------------------------------------------------------------
[2024-08-23 10:44:35,075] {taskinstance.py:1357} INFO - Starting attempt 1 of 1
[2024-08-23 10:44:35,075] {taskinstance.py:1358} INFO - 
--------------------------------------------------------------------------------
[2024-08-23 10:44:35,084] {taskinstance.py:1377} INFO - Executing <Task(PythonOperator): extract_data> on 2024-08-05 00:00:00+00:00
[2024-08-23 10:44:35,086] {standard_task_runner.py:52} INFO - Started process 39992 to run task
[2024-08-23 10:44:35,088] {standard_task_runner.py:79} INFO - Running: ['airflow', 'tasks', 'run', 'climate_data', 'extract_data', 'scheduled__2024-08-05T00:00:00+00:00', '--job-id', '10', '--raw', '--subdir', 'DAGS_FOLDER/climate_data.py', '--cfg-path', '/tmp/tmpcjn7jmmr', '--error-file', '/tmp/tmpv6wv613w']
[2024-08-23 10:44:35,088] {standard_task_runner.py:80} INFO - Job 10: Subtask extract_data
[2024-08-23 10:44:35,109] {task_command.py:370} INFO - Running <TaskInstance: climate_data.extract_data scheduled__2024-08-05T00:00:00+00:00 [running]> on host DESKTOP-TAQHM1V.
[2024-08-23 10:44:35,125] {taskinstance.py:1889} ERROR - Task failed with exception
Traceback (most recent call last):
  File "/root/Documentos/pipeline-airflow/venv/lib/python3.10/site-packages/airflow/models/taskinstance.py", line 1451, in _run_raw_task
    self._execute_task_with_callbacks(context, test_mode)
  File "/root/Documentos/pipeline-airflow/venv/lib/python3.10/site-packages/airflow/models/taskinstance.py", line 1555, in _execute_task_with_callbacks
    task_orig = self.render_templates(context=context)
  File "/root/Documentos/pipeline-airflow/venv/lib/python3.10/site-packages/airflow/models/taskinstance.py", line 2212, in render_templates
    rendered_task = self.task.render_template_fields(context)
  File "/root/Documentos/pipeline-airflow/venv/lib/python3.10/site-packages/airflow/models/baseoperator.py", line 1185, in render_template_fields
    self._do_render_template_fields(self, self.template_fields, context, jinja_env, set())
  File "/root/Documentos/pipeline-airflow/venv/lib/python3.10/site-packages/airflow/utils/session.py", line 71, in wrapper
    return func(*args, session=session, **kwargs)
  File "/root/Documentos/pipeline-airflow/venv/lib/python3.10/site-packages/airflow/models/abstractoperator.py", line 344, in _do_render_template_fields
    rendered_content = self.render_template(
  File "/root/Documentos/pipeline-airflow/venv/lib/python3.10/site-packages/airflow/models/abstractoperator.py", line 404, in render_template
    return {key: self.render_template(value, context, jinja_env) for key, value in value.items()}
  File "/root/Documentos/pipeline-airflow/venv/lib/python3.10/site-packages/airflow/models/abstractoperator.py", line 404, in <dictcomp>
    return {key: self.render_template(value, context, jinja_env) for key, value in value.items()}
  File "/root/Documentos/pipeline-airflow/venv/lib/python3.10/site-packages/airflow/models/abstractoperator.py", line 387, in render_template
    template = jinja_env.from_string(value)
  File "/root/Documentos/pipeline-airflow/venv/lib/python3.10/site-packages/jinja2/environment.py", line 1092, in from_string
    return cls.from_code(self, self.compile(source), gs, None)
  File "/root/Documentos/pipeline-airflow/venv/lib/python3.10/site-packages/jinja2/environment.py", line 757, in compile
    self.handle_exception(source=source_hint)
  File "/root/Documentos/pipeline-airflow/venv/lib/python3.10/site-packages/jinja2/environment.py", line 925, in handle_exception
    raise rewrite_traceback_stack(source=source)
  File "<unknown>", line 1, in template
jinja2.exceptions.TemplateSyntaxError: unexpected '%'
[2024-08-23 10:44:35,129] {taskinstance.py:1395} INFO - Marking task as FAILED. dag_id=climate_data, task_id=extract_data, execution_date=20240805T000000, start_date=20240823T134435, end_date=20240823T134435
[2024-08-23 10:44:35,136] {standard_task_runner.py:92} ERROR - Failed to execute job 10 for task extract_data (unexpected '%'; 39992)
[2024-08-23 10:44:35,140] {local_task_job.py:156} INFO - Task exited with return code 1
[2024-08-23 10:44:35,151] {local_task_job.py:273} INFO - 0 downstream tasks scheduled from follow-on schedule check
