[2024-08-23 10:38:22,184] {taskinstance.py:1159} INFO - Dependencies all met for <TaskInstance: climate_data.extract_data scheduled__2024-07-29T00:00:00+00:00 [queued]>
[2024-08-23 10:38:22,188] {taskinstance.py:1159} INFO - Dependencies all met for <TaskInstance: climate_data.extract_data scheduled__2024-07-29T00:00:00+00:00 [queued]>
[2024-08-23 10:38:22,188] {taskinstance.py:1356} INFO - 
--------------------------------------------------------------------------------
[2024-08-23 10:38:22,188] {taskinstance.py:1357} INFO - Starting attempt 1 of 1
[2024-08-23 10:38:22,188] {taskinstance.py:1358} INFO - 
--------------------------------------------------------------------------------
[2024-08-23 10:38:22,196] {taskinstance.py:1377} INFO - Executing <Task(PythonOperator): extract_data> on 2024-07-29 00:00:00+00:00
[2024-08-23 10:38:22,198] {standard_task_runner.py:52} INFO - Started process 37373 to run task
[2024-08-23 10:38:22,200] {standard_task_runner.py:79} INFO - Running: ['airflow', 'tasks', 'run', 'climate_data', 'extract_data', 'scheduled__2024-07-29T00:00:00+00:00', '--job-id', '8', '--raw', '--subdir', 'DAGS_FOLDER/climate_data.py', '--cfg-path', '/tmp/tmp731s_7sy', '--error-file', '/tmp/tmp0q3v8bh4']
[2024-08-23 10:38:22,200] {standard_task_runner.py:80} INFO - Job 8: Subtask extract_data
[2024-08-23 10:38:22,222] {task_command.py:370} INFO - Running <TaskInstance: climate_data.extract_data scheduled__2024-07-29T00:00:00+00:00 [running]> on host DESKTOP-TAQHM1V.
[2024-08-23 10:38:22,241] {taskinstance.py:1889} ERROR - Task failed with exception
Traceback (most recent call last):
  File "/root/Documentos/pipeline-airflow/venv/lib/python3.10/site-packages/airflow/models/taskinstance.py", line 1451, in _run_raw_task
    self._execute_task_with_callbacks(context, test_mode)
  File "/root/Documentos/pipeline-airflow/venv/lib/python3.10/site-packages/airflow/models/taskinstance.py", line 1555, in _execute_task_with_callbacks
    task_orig = self.render_templates(context=context)
  File "/root/Documentos/pipeline-airflow/venv/lib/python3.10/site-packages/airflow/models/taskinstance.py", line 2212, in render_templates
    rendered_task = self.task.render_template_fields(context)
  File "/root/Documentos/pipeline-airflow/venv/lib/python3.10/site-packages/airflow/models/baseoperator.py", line 1185, in render_template_fields
    self._do_render_template_fields(self, self.template_fields, context, jinja_env, set())
  File "/root/Documentos/pipeline-airflow/venv/lib/python3.10/site-packages/airflow/utils/session.py", line 71, in wrapper
    return func(*args, session=session, **kwargs)
  File "/root/Documentos/pipeline-airflow/venv/lib/python3.10/site-packages/airflow/models/abstractoperator.py", line 344, in _do_render_template_fields
    rendered_content = self.render_template(
  File "/root/Documentos/pipeline-airflow/venv/lib/python3.10/site-packages/airflow/models/abstractoperator.py", line 404, in render_template
    return {key: self.render_template(value, context, jinja_env) for key, value in value.items()}
  File "/root/Documentos/pipeline-airflow/venv/lib/python3.10/site-packages/airflow/models/abstractoperator.py", line 404, in <dictcomp>
    return {key: self.render_template(value, context, jinja_env) for key, value in value.items()}
  File "/root/Documentos/pipeline-airflow/venv/lib/python3.10/site-packages/airflow/models/abstractoperator.py", line 387, in render_template
    template = jinja_env.from_string(value)
  File "/root/Documentos/pipeline-airflow/venv/lib/python3.10/site-packages/jinja2/environment.py", line 1092, in from_string
    return cls.from_code(self, self.compile(source), gs, None)
  File "/root/Documentos/pipeline-airflow/venv/lib/python3.10/site-packages/jinja2/environment.py", line 757, in compile
    self.handle_exception(source=source_hint)
  File "/root/Documentos/pipeline-airflow/venv/lib/python3.10/site-packages/jinja2/environment.py", line 925, in handle_exception
    raise rewrite_traceback_stack(source=source)
  File "<unknown>", line 1, in template
jinja2.exceptions.TemplateSyntaxError: unexpected '%'
[2024-08-23 10:38:22,244] {taskinstance.py:1395} INFO - Marking task as FAILED. dag_id=climate_data, task_id=extract_data, execution_date=20240729T000000, start_date=20240823T133822, end_date=20240823T133822
[2024-08-23 10:38:22,254] {standard_task_runner.py:92} ERROR - Failed to execute job 8 for task extract_data (unexpected '%'; 37373)
[2024-08-23 10:38:22,292] {local_task_job.py:156} INFO - Task exited with return code 1
[2024-08-23 10:38:22,302] {local_task_job.py:273} INFO - 0 downstream tasks scheduled from follow-on schedule check
[2024-08-23 10:40:45,722] {taskinstance.py:1159} INFO - Dependencies all met for <TaskInstance: climate_data.extract_data scheduled__2024-07-29T00:00:00+00:00 [queued]>
[2024-08-23 10:40:45,725] {taskinstance.py:1159} INFO - Dependencies all met for <TaskInstance: climate_data.extract_data scheduled__2024-07-29T00:00:00+00:00 [queued]>
[2024-08-23 10:40:45,725] {taskinstance.py:1356} INFO - 
--------------------------------------------------------------------------------
[2024-08-23 10:40:45,725] {taskinstance.py:1357} INFO - Starting attempt 1 of 1
[2024-08-23 10:40:45,725] {taskinstance.py:1358} INFO - 
--------------------------------------------------------------------------------
[2024-08-23 10:40:45,734] {taskinstance.py:1377} INFO - Executing <Task(PythonOperator): extract_data> on 2024-07-29 00:00:00+00:00
[2024-08-23 10:40:45,736] {standard_task_runner.py:52} INFO - Started process 38397 to run task
[2024-08-23 10:40:45,738] {standard_task_runner.py:79} INFO - Running: ['airflow', 'tasks', 'run', 'climate_data', 'extract_data', 'scheduled__2024-07-29T00:00:00+00:00', '--job-id', '8', '--raw', '--subdir', 'DAGS_FOLDER/climate_data.py', '--cfg-path', '/tmp/tmpdbzlr88a', '--error-file', '/tmp/tmpnxhqwqan']
[2024-08-23 10:40:45,738] {standard_task_runner.py:80} INFO - Job 8: Subtask extract_data
[2024-08-23 10:40:45,758] {task_command.py:370} INFO - Running <TaskInstance: climate_data.extract_data scheduled__2024-07-29T00:00:00+00:00 [running]> on host DESKTOP-TAQHM1V.
[2024-08-23 10:40:45,773] {taskinstance.py:1889} ERROR - Task failed with exception
Traceback (most recent call last):
  File "/root/Documentos/pipeline-airflow/venv/lib/python3.10/site-packages/airflow/models/taskinstance.py", line 1451, in _run_raw_task
    self._execute_task_with_callbacks(context, test_mode)
  File "/root/Documentos/pipeline-airflow/venv/lib/python3.10/site-packages/airflow/models/taskinstance.py", line 1555, in _execute_task_with_callbacks
    task_orig = self.render_templates(context=context)
  File "/root/Documentos/pipeline-airflow/venv/lib/python3.10/site-packages/airflow/models/taskinstance.py", line 2212, in render_templates
    rendered_task = self.task.render_template_fields(context)
  File "/root/Documentos/pipeline-airflow/venv/lib/python3.10/site-packages/airflow/models/baseoperator.py", line 1185, in render_template_fields
    self._do_render_template_fields(self, self.template_fields, context, jinja_env, set())
  File "/root/Documentos/pipeline-airflow/venv/lib/python3.10/site-packages/airflow/utils/session.py", line 71, in wrapper
    return func(*args, session=session, **kwargs)
  File "/root/Documentos/pipeline-airflow/venv/lib/python3.10/site-packages/airflow/models/abstractoperator.py", line 344, in _do_render_template_fields
    rendered_content = self.render_template(
  File "/root/Documentos/pipeline-airflow/venv/lib/python3.10/site-packages/airflow/models/abstractoperator.py", line 404, in render_template
    return {key: self.render_template(value, context, jinja_env) for key, value in value.items()}
  File "/root/Documentos/pipeline-airflow/venv/lib/python3.10/site-packages/airflow/models/abstractoperator.py", line 404, in <dictcomp>
    return {key: self.render_template(value, context, jinja_env) for key, value in value.items()}
  File "/root/Documentos/pipeline-airflow/venv/lib/python3.10/site-packages/airflow/models/abstractoperator.py", line 387, in render_template
    template = jinja_env.from_string(value)
  File "/root/Documentos/pipeline-airflow/venv/lib/python3.10/site-packages/jinja2/environment.py", line 1092, in from_string
    return cls.from_code(self, self.compile(source), gs, None)
  File "/root/Documentos/pipeline-airflow/venv/lib/python3.10/site-packages/jinja2/environment.py", line 757, in compile
    self.handle_exception(source=source_hint)
  File "/root/Documentos/pipeline-airflow/venv/lib/python3.10/site-packages/jinja2/environment.py", line 925, in handle_exception
    raise rewrite_traceback_stack(source=source)
  File "<unknown>", line 1, in template
jinja2.exceptions.TemplateSyntaxError: unexpected '%'
[2024-08-23 10:40:45,775] {taskinstance.py:1395} INFO - Marking task as FAILED. dag_id=climate_data, task_id=extract_data, execution_date=20240729T000000, start_date=20240823T134045, end_date=20240823T134045
[2024-08-23 10:40:45,782] {standard_task_runner.py:92} ERROR - Failed to execute job 8 for task extract_data (unexpected '%'; 38397)
[2024-08-23 10:40:45,790] {local_task_job.py:156} INFO - Task exited with return code 1
[2024-08-23 10:40:45,799] {local_task_job.py:273} INFO - 0 downstream tasks scheduled from follow-on schedule check
[2024-08-23 10:44:32,511] {taskinstance.py:1159} INFO - Dependencies all met for <TaskInstance: climate_data.extract_data scheduled__2024-07-29T00:00:00+00:00 [queued]>
[2024-08-23 10:44:32,514] {taskinstance.py:1159} INFO - Dependencies all met for <TaskInstance: climate_data.extract_data scheduled__2024-07-29T00:00:00+00:00 [queued]>
[2024-08-23 10:44:32,514] {taskinstance.py:1356} INFO - 
--------------------------------------------------------------------------------
[2024-08-23 10:44:32,515] {taskinstance.py:1357} INFO - Starting attempt 1 of 1
[2024-08-23 10:44:32,515] {taskinstance.py:1358} INFO - 
--------------------------------------------------------------------------------
[2024-08-23 10:44:32,522] {taskinstance.py:1377} INFO - Executing <Task(PythonOperator): extract_data> on 2024-07-29 00:00:00+00:00
[2024-08-23 10:44:32,524] {standard_task_runner.py:52} INFO - Started process 39949 to run task
[2024-08-23 10:44:32,526] {standard_task_runner.py:79} INFO - Running: ['airflow', 'tasks', 'run', 'climate_data', 'extract_data', 'scheduled__2024-07-29T00:00:00+00:00', '--job-id', '8', '--raw', '--subdir', 'DAGS_FOLDER/climate_data.py', '--cfg-path', '/tmp/tmpdgt765kr', '--error-file', '/tmp/tmpk0thog2_']
[2024-08-23 10:44:32,526] {standard_task_runner.py:80} INFO - Job 8: Subtask extract_data
[2024-08-23 10:44:32,547] {task_command.py:370} INFO - Running <TaskInstance: climate_data.extract_data scheduled__2024-07-29T00:00:00+00:00 [running]> on host DESKTOP-TAQHM1V.
[2024-08-23 10:44:32,561] {taskinstance.py:1889} ERROR - Task failed with exception
Traceback (most recent call last):
  File "/root/Documentos/pipeline-airflow/venv/lib/python3.10/site-packages/airflow/models/taskinstance.py", line 1451, in _run_raw_task
    self._execute_task_with_callbacks(context, test_mode)
  File "/root/Documentos/pipeline-airflow/venv/lib/python3.10/site-packages/airflow/models/taskinstance.py", line 1555, in _execute_task_with_callbacks
    task_orig = self.render_templates(context=context)
  File "/root/Documentos/pipeline-airflow/venv/lib/python3.10/site-packages/airflow/models/taskinstance.py", line 2212, in render_templates
    rendered_task = self.task.render_template_fields(context)
  File "/root/Documentos/pipeline-airflow/venv/lib/python3.10/site-packages/airflow/models/baseoperator.py", line 1185, in render_template_fields
    self._do_render_template_fields(self, self.template_fields, context, jinja_env, set())
  File "/root/Documentos/pipeline-airflow/venv/lib/python3.10/site-packages/airflow/utils/session.py", line 71, in wrapper
    return func(*args, session=session, **kwargs)
  File "/root/Documentos/pipeline-airflow/venv/lib/python3.10/site-packages/airflow/models/abstractoperator.py", line 344, in _do_render_template_fields
    rendered_content = self.render_template(
  File "/root/Documentos/pipeline-airflow/venv/lib/python3.10/site-packages/airflow/models/abstractoperator.py", line 404, in render_template
    return {key: self.render_template(value, context, jinja_env) for key, value in value.items()}
  File "/root/Documentos/pipeline-airflow/venv/lib/python3.10/site-packages/airflow/models/abstractoperator.py", line 404, in <dictcomp>
    return {key: self.render_template(value, context, jinja_env) for key, value in value.items()}
  File "/root/Documentos/pipeline-airflow/venv/lib/python3.10/site-packages/airflow/models/abstractoperator.py", line 387, in render_template
    template = jinja_env.from_string(value)
  File "/root/Documentos/pipeline-airflow/venv/lib/python3.10/site-packages/jinja2/environment.py", line 1092, in from_string
    return cls.from_code(self, self.compile(source), gs, None)
  File "/root/Documentos/pipeline-airflow/venv/lib/python3.10/site-packages/jinja2/environment.py", line 757, in compile
    self.handle_exception(source=source_hint)
  File "/root/Documentos/pipeline-airflow/venv/lib/python3.10/site-packages/jinja2/environment.py", line 925, in handle_exception
    raise rewrite_traceback_stack(source=source)
  File "<unknown>", line 1, in template
jinja2.exceptions.TemplateSyntaxError: unexpected '%'
[2024-08-23 10:44:32,564] {taskinstance.py:1395} INFO - Marking task as FAILED. dag_id=climate_data, task_id=extract_data, execution_date=20240729T000000, start_date=20240823T134432, end_date=20240823T134432
[2024-08-23 10:44:32,571] {standard_task_runner.py:92} ERROR - Failed to execute job 8 for task extract_data (unexpected '%'; 39949)
[2024-08-23 10:44:32,578] {local_task_job.py:156} INFO - Task exited with return code 1
[2024-08-23 10:44:32,589] {local_task_job.py:273} INFO - 0 downstream tasks scheduled from follow-on schedule check
