[2024-08-23 10:38:26,277] {taskinstance.py:1159} INFO - Dependencies all met for <TaskInstance: climate_data.extract_data scheduled__2024-08-12T00:00:00+00:00 [queued]>
[2024-08-23 10:38:26,281] {taskinstance.py:1159} INFO - Dependencies all met for <TaskInstance: climate_data.extract_data scheduled__2024-08-12T00:00:00+00:00 [queued]>
[2024-08-23 10:38:26,281] {taskinstance.py:1356} INFO - 
--------------------------------------------------------------------------------
[2024-08-23 10:38:26,281] {taskinstance.py:1357} INFO - Starting attempt 1 of 1
[2024-08-23 10:38:26,281] {taskinstance.py:1358} INFO - 
--------------------------------------------------------------------------------
[2024-08-23 10:38:26,289] {taskinstance.py:1377} INFO - Executing <Task(PythonOperator): extract_data> on 2024-08-12 00:00:00+00:00
[2024-08-23 10:38:26,291] {standard_task_runner.py:52} INFO - Started process 37439 to run task
[2024-08-23 10:38:26,293] {standard_task_runner.py:79} INFO - Running: ['airflow', 'tasks', 'run', 'climate_data', 'extract_data', 'scheduled__2024-08-12T00:00:00+00:00', '--job-id', '11', '--raw', '--subdir', 'DAGS_FOLDER/climate_data.py', '--cfg-path', '/tmp/tmpvup6jlso', '--error-file', '/tmp/tmpdb05k526']
[2024-08-23 10:38:26,293] {standard_task_runner.py:80} INFO - Job 11: Subtask extract_data
[2024-08-23 10:38:26,317] {task_command.py:370} INFO - Running <TaskInstance: climate_data.extract_data scheduled__2024-08-12T00:00:00+00:00 [running]> on host DESKTOP-TAQHM1V.
[2024-08-23 10:38:26,333] {taskinstance.py:1889} ERROR - Task failed with exception
Traceback (most recent call last):
  File "/root/Documentos/pipeline-airflow/venv/lib/python3.10/site-packages/airflow/models/taskinstance.py", line 1451, in _run_raw_task
    self._execute_task_with_callbacks(context, test_mode)
  File "/root/Documentos/pipeline-airflow/venv/lib/python3.10/site-packages/airflow/models/taskinstance.py", line 1555, in _execute_task_with_callbacks
    task_orig = self.render_templates(context=context)
  File "/root/Documentos/pipeline-airflow/venv/lib/python3.10/site-packages/airflow/models/taskinstance.py", line 2212, in render_templates
    rendered_task = self.task.render_template_fields(context)
  File "/root/Documentos/pipeline-airflow/venv/lib/python3.10/site-packages/airflow/models/baseoperator.py", line 1185, in render_template_fields
    self._do_render_template_fields(self, self.template_fields, context, jinja_env, set())
  File "/root/Documentos/pipeline-airflow/venv/lib/python3.10/site-packages/airflow/utils/session.py", line 71, in wrapper
    return func(*args, session=session, **kwargs)
  File "/root/Documentos/pipeline-airflow/venv/lib/python3.10/site-packages/airflow/models/abstractoperator.py", line 344, in _do_render_template_fields
    rendered_content = self.render_template(
  File "/root/Documentos/pipeline-airflow/venv/lib/python3.10/site-packages/airflow/models/abstractoperator.py", line 404, in render_template
    return {key: self.render_template(value, context, jinja_env) for key, value in value.items()}
  File "/root/Documentos/pipeline-airflow/venv/lib/python3.10/site-packages/airflow/models/abstractoperator.py", line 404, in <dictcomp>
    return {key: self.render_template(value, context, jinja_env) for key, value in value.items()}
  File "/root/Documentos/pipeline-airflow/venv/lib/python3.10/site-packages/airflow/models/abstractoperator.py", line 387, in render_template
    template = jinja_env.from_string(value)
  File "/root/Documentos/pipeline-airflow/venv/lib/python3.10/site-packages/jinja2/environment.py", line 1092, in from_string
    return cls.from_code(self, self.compile(source), gs, None)
  File "/root/Documentos/pipeline-airflow/venv/lib/python3.10/site-packages/jinja2/environment.py", line 757, in compile
    self.handle_exception(source=source_hint)
  File "/root/Documentos/pipeline-airflow/venv/lib/python3.10/site-packages/jinja2/environment.py", line 925, in handle_exception
    raise rewrite_traceback_stack(source=source)
  File "<unknown>", line 1, in template
jinja2.exceptions.TemplateSyntaxError: unexpected '%'
[2024-08-23 10:38:26,336] {taskinstance.py:1395} INFO - Marking task as FAILED. dag_id=climate_data, task_id=extract_data, execution_date=20240812T000000, start_date=20240823T133826, end_date=20240823T133826
[2024-08-23 10:38:26,343] {standard_task_runner.py:92} ERROR - Failed to execute job 11 for task extract_data (unexpected '%'; 37439)
[2024-08-23 10:38:26,386] {local_task_job.py:156} INFO - Task exited with return code 1
[2024-08-23 10:38:26,397] {local_task_job.py:273} INFO - 0 downstream tasks scheduled from follow-on schedule check
[2024-08-23 10:40:49,638] {taskinstance.py:1159} INFO - Dependencies all met for <TaskInstance: climate_data.extract_data scheduled__2024-08-12T00:00:00+00:00 [queued]>
[2024-08-23 10:40:49,642] {taskinstance.py:1159} INFO - Dependencies all met for <TaskInstance: climate_data.extract_data scheduled__2024-08-12T00:00:00+00:00 [queued]>
[2024-08-23 10:40:49,642] {taskinstance.py:1356} INFO - 
--------------------------------------------------------------------------------
[2024-08-23 10:40:49,642] {taskinstance.py:1357} INFO - Starting attempt 1 of 1
[2024-08-23 10:40:49,642] {taskinstance.py:1358} INFO - 
--------------------------------------------------------------------------------
[2024-08-23 10:40:49,651] {taskinstance.py:1377} INFO - Executing <Task(PythonOperator): extract_data> on 2024-08-12 00:00:00+00:00
[2024-08-23 10:40:49,653] {standard_task_runner.py:52} INFO - Started process 38460 to run task
[2024-08-23 10:40:49,655] {standard_task_runner.py:79} INFO - Running: ['airflow', 'tasks', 'run', 'climate_data', 'extract_data', 'scheduled__2024-08-12T00:00:00+00:00', '--job-id', '11', '--raw', '--subdir', 'DAGS_FOLDER/climate_data.py', '--cfg-path', '/tmp/tmp45peocsd', '--error-file', '/tmp/tmp_dhz0y04']
[2024-08-23 10:40:49,655] {standard_task_runner.py:80} INFO - Job 11: Subtask extract_data
[2024-08-23 10:40:49,676] {task_command.py:370} INFO - Running <TaskInstance: climate_data.extract_data scheduled__2024-08-12T00:00:00+00:00 [running]> on host DESKTOP-TAQHM1V.
[2024-08-23 10:40:49,691] {taskinstance.py:1889} ERROR - Task failed with exception
Traceback (most recent call last):
  File "/root/Documentos/pipeline-airflow/venv/lib/python3.10/site-packages/airflow/models/taskinstance.py", line 1451, in _run_raw_task
    self._execute_task_with_callbacks(context, test_mode)
  File "/root/Documentos/pipeline-airflow/venv/lib/python3.10/site-packages/airflow/models/taskinstance.py", line 1555, in _execute_task_with_callbacks
    task_orig = self.render_templates(context=context)
  File "/root/Documentos/pipeline-airflow/venv/lib/python3.10/site-packages/airflow/models/taskinstance.py", line 2212, in render_templates
    rendered_task = self.task.render_template_fields(context)
  File "/root/Documentos/pipeline-airflow/venv/lib/python3.10/site-packages/airflow/models/baseoperator.py", line 1185, in render_template_fields
    self._do_render_template_fields(self, self.template_fields, context, jinja_env, set())
  File "/root/Documentos/pipeline-airflow/venv/lib/python3.10/site-packages/airflow/utils/session.py", line 71, in wrapper
    return func(*args, session=session, **kwargs)
  File "/root/Documentos/pipeline-airflow/venv/lib/python3.10/site-packages/airflow/models/abstractoperator.py", line 344, in _do_render_template_fields
    rendered_content = self.render_template(
  File "/root/Documentos/pipeline-airflow/venv/lib/python3.10/site-packages/airflow/models/abstractoperator.py", line 404, in render_template
    return {key: self.render_template(value, context, jinja_env) for key, value in value.items()}
  File "/root/Documentos/pipeline-airflow/venv/lib/python3.10/site-packages/airflow/models/abstractoperator.py", line 404, in <dictcomp>
    return {key: self.render_template(value, context, jinja_env) for key, value in value.items()}
  File "/root/Documentos/pipeline-airflow/venv/lib/python3.10/site-packages/airflow/models/abstractoperator.py", line 387, in render_template
    template = jinja_env.from_string(value)
  File "/root/Documentos/pipeline-airflow/venv/lib/python3.10/site-packages/jinja2/environment.py", line 1092, in from_string
    return cls.from_code(self, self.compile(source), gs, None)
  File "/root/Documentos/pipeline-airflow/venv/lib/python3.10/site-packages/jinja2/environment.py", line 757, in compile
    self.handle_exception(source=source_hint)
  File "/root/Documentos/pipeline-airflow/venv/lib/python3.10/site-packages/jinja2/environment.py", line 925, in handle_exception
    raise rewrite_traceback_stack(source=source)
  File "<unknown>", line 1, in template
jinja2.exceptions.TemplateSyntaxError: unexpected '%'
[2024-08-23 10:40:49,694] {taskinstance.py:1395} INFO - Marking task as FAILED. dag_id=climate_data, task_id=extract_data, execution_date=20240812T000000, start_date=20240823T134049, end_date=20240823T134049
[2024-08-23 10:40:49,700] {standard_task_runner.py:92} ERROR - Failed to execute job 11 for task extract_data (unexpected '%'; 38460)
[2024-08-23 10:40:49,707] {local_task_job.py:156} INFO - Task exited with return code 1
[2024-08-23 10:40:49,717] {local_task_job.py:273} INFO - 0 downstream tasks scheduled from follow-on schedule check
[2024-08-23 10:44:36,430] {taskinstance.py:1159} INFO - Dependencies all met for <TaskInstance: climate_data.extract_data scheduled__2024-08-12T00:00:00+00:00 [queued]>
[2024-08-23 10:44:36,433] {taskinstance.py:1159} INFO - Dependencies all met for <TaskInstance: climate_data.extract_data scheduled__2024-08-12T00:00:00+00:00 [queued]>
[2024-08-23 10:44:36,433] {taskinstance.py:1356} INFO - 
--------------------------------------------------------------------------------
[2024-08-23 10:44:36,433] {taskinstance.py:1357} INFO - Starting attempt 1 of 1
[2024-08-23 10:44:36,433] {taskinstance.py:1358} INFO - 
--------------------------------------------------------------------------------
[2024-08-23 10:44:36,441] {taskinstance.py:1377} INFO - Executing <Task(PythonOperator): extract_data> on 2024-08-12 00:00:00+00:00
[2024-08-23 10:44:36,443] {standard_task_runner.py:52} INFO - Started process 40014 to run task
[2024-08-23 10:44:36,445] {standard_task_runner.py:79} INFO - Running: ['airflow', 'tasks', 'run', 'climate_data', 'extract_data', 'scheduled__2024-08-12T00:00:00+00:00', '--job-id', '11', '--raw', '--subdir', 'DAGS_FOLDER/climate_data.py', '--cfg-path', '/tmp/tmp88pborpg', '--error-file', '/tmp/tmp37vfjc2v']
[2024-08-23 10:44:36,445] {standard_task_runner.py:80} INFO - Job 11: Subtask extract_data
[2024-08-23 10:44:36,466] {task_command.py:370} INFO - Running <TaskInstance: climate_data.extract_data scheduled__2024-08-12T00:00:00+00:00 [running]> on host DESKTOP-TAQHM1V.
[2024-08-23 10:44:36,481] {taskinstance.py:1889} ERROR - Task failed with exception
Traceback (most recent call last):
  File "/root/Documentos/pipeline-airflow/venv/lib/python3.10/site-packages/airflow/models/taskinstance.py", line 1451, in _run_raw_task
    self._execute_task_with_callbacks(context, test_mode)
  File "/root/Documentos/pipeline-airflow/venv/lib/python3.10/site-packages/airflow/models/taskinstance.py", line 1555, in _execute_task_with_callbacks
    task_orig = self.render_templates(context=context)
  File "/root/Documentos/pipeline-airflow/venv/lib/python3.10/site-packages/airflow/models/taskinstance.py", line 2212, in render_templates
    rendered_task = self.task.render_template_fields(context)
  File "/root/Documentos/pipeline-airflow/venv/lib/python3.10/site-packages/airflow/models/baseoperator.py", line 1185, in render_template_fields
    self._do_render_template_fields(self, self.template_fields, context, jinja_env, set())
  File "/root/Documentos/pipeline-airflow/venv/lib/python3.10/site-packages/airflow/utils/session.py", line 71, in wrapper
    return func(*args, session=session, **kwargs)
  File "/root/Documentos/pipeline-airflow/venv/lib/python3.10/site-packages/airflow/models/abstractoperator.py", line 344, in _do_render_template_fields
    rendered_content = self.render_template(
  File "/root/Documentos/pipeline-airflow/venv/lib/python3.10/site-packages/airflow/models/abstractoperator.py", line 404, in render_template
    return {key: self.render_template(value, context, jinja_env) for key, value in value.items()}
  File "/root/Documentos/pipeline-airflow/venv/lib/python3.10/site-packages/airflow/models/abstractoperator.py", line 404, in <dictcomp>
    return {key: self.render_template(value, context, jinja_env) for key, value in value.items()}
  File "/root/Documentos/pipeline-airflow/venv/lib/python3.10/site-packages/airflow/models/abstractoperator.py", line 387, in render_template
    template = jinja_env.from_string(value)
  File "/root/Documentos/pipeline-airflow/venv/lib/python3.10/site-packages/jinja2/environment.py", line 1092, in from_string
    return cls.from_code(self, self.compile(source), gs, None)
  File "/root/Documentos/pipeline-airflow/venv/lib/python3.10/site-packages/jinja2/environment.py", line 757, in compile
    self.handle_exception(source=source_hint)
  File "/root/Documentos/pipeline-airflow/venv/lib/python3.10/site-packages/jinja2/environment.py", line 925, in handle_exception
    raise rewrite_traceback_stack(source=source)
  File "<unknown>", line 1, in template
jinja2.exceptions.TemplateSyntaxError: unexpected '%'
[2024-08-23 10:44:36,483] {taskinstance.py:1395} INFO - Marking task as FAILED. dag_id=climate_data, task_id=extract_data, execution_date=20240812T000000, start_date=20240823T134436, end_date=20240823T134436
[2024-08-23 10:44:36,490] {standard_task_runner.py:92} ERROR - Failed to execute job 11 for task extract_data (unexpected '%'; 40014)
[2024-08-23 10:44:36,497] {local_task_job.py:156} INFO - Task exited with return code 1
[2024-08-23 10:44:36,507] {local_task_job.py:273} INFO - 0 downstream tasks scheduled from follow-on schedule check
